{
 "cells": [
  {
   "cell_type": "code",
   "execution_count": 19,
   "metadata": {},
   "outputs": [
    {
     "name": "stdout",
     "output_type": "stream",
     "text": [
      "Requirement already satisfied: opencv-python in c:\\users\\acer\\appdata\\local\\packages\\pythonsoftwarefoundation.python.3.12_qbz5n2kfra8p0\\localcache\\local-packages\\python312\\site-packages (4.11.0.86)\n",
      "Requirement already satisfied: numpy>=1.21.2 in c:\\users\\acer\\appdata\\local\\packages\\pythonsoftwarefoundation.python.3.12_qbz5n2kfra8p0\\localcache\\local-packages\\python312\\site-packages (from opencv-python) (2.0.2)\n"
     ]
    }
   ],
   "source": [
    "!pip  install --user opencv-python"
   ]
  },
  {
   "cell_type": "code",
   "execution_count": 27,
   "metadata": {},
   "outputs": [
    {
     "name": "stdout",
     "output_type": "stream",
     "text": [
      "Requirement already satisfied: pip in c:\\program files\\windowsapps\\pythonsoftwarefoundation.python.3.12_3.12.2288.0_x64__qbz5n2kfra8p0\\lib\\site-packages (24.3.1)\n"
     ]
    }
   ],
   "source": [
    "!pip  install --user --upgrade pip "
   ]
  },
  {
   "cell_type": "code",
   "execution_count": null,
   "metadata": {},
   "outputs": [
    {
     "name": "stdout",
     "output_type": "stream",
     "text": [
      "Collecting tensorflow\n",
      "  Using cached tensorflow-2.18.0-cp312-cp312-win_amd64.whl.metadata (3.3 kB)\n",
      "Collecting tensorflow-intel==2.18.0 (from tensorflow)\n",
      "  Using cached tensorflow_intel-2.18.0-cp312-cp312-win_amd64.whl.metadata (4.9 kB)\n",
      "Requirement already satisfied: absl-py>=1.0.0 in c:\\users\\acer\\appdata\\local\\packages\\pythonsoftwarefoundation.python.3.12_qbz5n2kfra8p0\\localcache\\local-packages\\python312\\site-packages (from tensorflow-intel==2.18.0->tensorflow) (2.1.0)\n",
      "Requirement already satisfied: astunparse>=1.6.0 in c:\\users\\acer\\appdata\\local\\packages\\pythonsoftwarefoundation.python.3.12_qbz5n2kfra8p0\\localcache\\local-packages\\python312\\site-packages (from tensorflow-intel==2.18.0->tensorflow) (1.6.3)\n",
      "Requirement already satisfied: flatbuffers>=24.3.25 in c:\\users\\acer\\appdata\\local\\packages\\pythonsoftwarefoundation.python.3.12_qbz5n2kfra8p0\\localcache\\local-packages\\python312\\site-packages (from tensorflow-intel==2.18.0->tensorflow) (25.1.21)\n",
      "Requirement already satisfied: gast!=0.5.0,!=0.5.1,!=0.5.2,>=0.2.1 in c:\\users\\acer\\appdata\\local\\packages\\pythonsoftwarefoundation.python.3.12_qbz5n2kfra8p0\\localcache\\local-packages\\python312\\site-packages (from tensorflow-intel==2.18.0->tensorflow) (0.6.0)\n",
      "Requirement already satisfied: google-pasta>=0.1.1 in c:\\users\\acer\\appdata\\local\\packages\\pythonsoftwarefoundation.python.3.12_qbz5n2kfra8p0\\localcache\\local-packages\\python312\\site-packages (from tensorflow-intel==2.18.0->tensorflow) (0.2.0)\n",
      "Requirement already satisfied: libclang>=13.0.0 in c:\\users\\acer\\appdata\\local\\packages\\pythonsoftwarefoundation.python.3.12_qbz5n2kfra8p0\\localcache\\local-packages\\python312\\site-packages (from tensorflow-intel==2.18.0->tensorflow) (18.1.1)\n",
      "Requirement already satisfied: opt-einsum>=2.3.2 in c:\\users\\acer\\appdata\\local\\packages\\pythonsoftwarefoundation.python.3.12_qbz5n2kfra8p0\\localcache\\local-packages\\python312\\site-packages (from tensorflow-intel==2.18.0->tensorflow) (3.4.0)\n",
      "Requirement already satisfied: packaging in c:\\users\\acer\\appdata\\local\\packages\\pythonsoftwarefoundation.python.3.12_qbz5n2kfra8p0\\localcache\\local-packages\\python312\\site-packages (from tensorflow-intel==2.18.0->tensorflow) (24.2)\n",
      "Requirement already satisfied: protobuf!=4.21.0,!=4.21.1,!=4.21.2,!=4.21.3,!=4.21.4,!=4.21.5,<6.0.0dev,>=3.20.3 in c:\\users\\acer\\appdata\\local\\packages\\pythonsoftwarefoundation.python.3.12_qbz5n2kfra8p0\\localcache\\local-packages\\python312\\site-packages (from tensorflow-intel==2.18.0->tensorflow) (5.29.3)\n",
      "Requirement already satisfied: requests<3,>=2.21.0 in c:\\users\\acer\\appdata\\local\\packages\\pythonsoftwarefoundation.python.3.12_qbz5n2kfra8p0\\localcache\\local-packages\\python312\\site-packages (from tensorflow-intel==2.18.0->tensorflow) (2.32.3)\n",
      "Requirement already satisfied: setuptools in c:\\users\\acer\\appdata\\local\\packages\\pythonsoftwarefoundation.python.3.12_qbz5n2kfra8p0\\localcache\\local-packages\\python312\\site-packages (from tensorflow-intel==2.18.0->tensorflow) (75.8.0)\n",
      "Requirement already satisfied: six>=1.12.0 in c:\\users\\acer\\appdata\\local\\packages\\pythonsoftwarefoundation.python.3.12_qbz5n2kfra8p0\\localcache\\local-packages\\python312\\site-packages (from tensorflow-intel==2.18.0->tensorflow) (1.17.0)\n",
      "Requirement already satisfied: termcolor>=1.1.0 in c:\\users\\acer\\appdata\\local\\packages\\pythonsoftwarefoundation.python.3.12_qbz5n2kfra8p0\\localcache\\local-packages\\python312\\site-packages (from tensorflow-intel==2.18.0->tensorflow) (2.5.0)\n",
      "Requirement already satisfied: typing-extensions>=3.6.6 in c:\\users\\acer\\appdata\\local\\packages\\pythonsoftwarefoundation.python.3.12_qbz5n2kfra8p0\\localcache\\local-packages\\python312\\site-packages (from tensorflow-intel==2.18.0->tensorflow) (4.12.2)\n",
      "Requirement already satisfied: wrapt>=1.11.0 in c:\\users\\acer\\appdata\\local\\packages\\pythonsoftwarefoundation.python.3.12_qbz5n2kfra8p0\\localcache\\local-packages\\python312\\site-packages (from tensorflow-intel==2.18.0->tensorflow) (1.17.2)\n",
      "Requirement already satisfied: grpcio<2.0,>=1.24.3 in c:\\users\\acer\\appdata\\local\\packages\\pythonsoftwarefoundation.python.3.12_qbz5n2kfra8p0\\localcache\\local-packages\\python312\\site-packages (from tensorflow-intel==2.18.0->tensorflow) (1.70.0)\n",
      "Requirement already satisfied: tensorboard<2.19,>=2.18 in c:\\users\\acer\\appdata\\local\\packages\\pythonsoftwarefoundation.python.3.12_qbz5n2kfra8p0\\localcache\\local-packages\\python312\\site-packages (from tensorflow-intel==2.18.0->tensorflow) (2.18.0)\n",
      "Requirement already satisfied: keras>=3.5.0 in c:\\users\\acer\\appdata\\local\\packages\\pythonsoftwarefoundation.python.3.12_qbz5n2kfra8p0\\localcache\\local-packages\\python312\\site-packages (from tensorflow-intel==2.18.0->tensorflow) (3.8.0)\n",
      "Requirement already satisfied: numpy<2.1.0,>=1.26.0 in c:\\users\\acer\\appdata\\local\\packages\\pythonsoftwarefoundation.python.3.12_qbz5n2kfra8p0\\localcache\\local-packages\\python312\\site-packages (from tensorflow-intel==2.18.0->tensorflow) (2.0.2)\n",
      "Requirement already satisfied: h5py>=3.11.0 in c:\\users\\acer\\appdata\\local\\packages\\pythonsoftwarefoundation.python.3.12_qbz5n2kfra8p0\\localcache\\local-packages\\python312\\site-packages (from tensorflow-intel==2.18.0->tensorflow) (3.12.1)\n",
      "Requirement already satisfied: ml-dtypes<0.5.0,>=0.4.0 in c:\\users\\acer\\appdata\\local\\packages\\pythonsoftwarefoundation.python.3.12_qbz5n2kfra8p0\\localcache\\local-packages\\python312\\site-packages (from tensorflow-intel==2.18.0->tensorflow) (0.4.1)\n",
      "Requirement already satisfied: wheel<1.0,>=0.23.0 in c:\\users\\acer\\appdata\\local\\packages\\pythonsoftwarefoundation.python.3.12_qbz5n2kfra8p0\\localcache\\local-packages\\python312\\site-packages (from astunparse>=1.6.0->tensorflow-intel==2.18.0->tensorflow) (0.45.1)\n",
      "Requirement already satisfied: rich in c:\\users\\acer\\appdata\\local\\packages\\pythonsoftwarefoundation.python.3.12_qbz5n2kfra8p0\\localcache\\local-packages\\python312\\site-packages (from keras>=3.5.0->tensorflow-intel==2.18.0->tensorflow) (13.9.4)\n",
      "Requirement already satisfied: namex in c:\\users\\acer\\appdata\\local\\packages\\pythonsoftwarefoundation.python.3.12_qbz5n2kfra8p0\\localcache\\local-packages\\python312\\site-packages (from keras>=3.5.0->tensorflow-intel==2.18.0->tensorflow) (0.0.8)\n",
      "Requirement already satisfied: optree in c:\\users\\acer\\appdata\\local\\packages\\pythonsoftwarefoundation.python.3.12_qbz5n2kfra8p0\\localcache\\local-packages\\python312\\site-packages (from keras>=3.5.0->tensorflow-intel==2.18.0->tensorflow) (0.14.0)\n",
      "Requirement already satisfied: charset-normalizer<4,>=2 in c:\\users\\acer\\appdata\\local\\packages\\pythonsoftwarefoundation.python.3.12_qbz5n2kfra8p0\\localcache\\local-packages\\python312\\site-packages (from requests<3,>=2.21.0->tensorflow-intel==2.18.0->tensorflow) (3.4.1)\n",
      "Requirement already satisfied: idna<4,>=2.5 in c:\\users\\acer\\appdata\\local\\packages\\pythonsoftwarefoundation.python.3.12_qbz5n2kfra8p0\\localcache\\local-packages\\python312\\site-packages (from requests<3,>=2.21.0->tensorflow-intel==2.18.0->tensorflow) (3.10)\n",
      "Requirement already satisfied: urllib3<3,>=1.21.1 in c:\\users\\acer\\appdata\\local\\packages\\pythonsoftwarefoundation.python.3.12_qbz5n2kfra8p0\\localcache\\local-packages\\python312\\site-packages (from requests<3,>=2.21.0->tensorflow-intel==2.18.0->tensorflow) (2.3.0)\n",
      "Requirement already satisfied: certifi>=2017.4.17 in c:\\users\\acer\\appdata\\local\\packages\\pythonsoftwarefoundation.python.3.12_qbz5n2kfra8p0\\localcache\\local-packages\\python312\\site-packages (from requests<3,>=2.21.0->tensorflow-intel==2.18.0->tensorflow) (2024.12.14)\n",
      "Requirement already satisfied: markdown>=2.6.8 in c:\\users\\acer\\appdata\\local\\packages\\pythonsoftwarefoundation.python.3.12_qbz5n2kfra8p0\\localcache\\local-packages\\python312\\site-packages (from tensorboard<2.19,>=2.18->tensorflow-intel==2.18.0->tensorflow) (3.7)\n",
      "Requirement already satisfied: tensorboard-data-server<0.8.0,>=0.7.0 in c:\\users\\acer\\appdata\\local\\packages\\pythonsoftwarefoundation.python.3.12_qbz5n2kfra8p0\\localcache\\local-packages\\python312\\site-packages (from tensorboard<2.19,>=2.18->tensorflow-intel==2.18.0->tensorflow) (0.7.2)\n",
      "Requirement already satisfied: werkzeug>=1.0.1 in c:\\users\\acer\\appdata\\local\\packages\\pythonsoftwarefoundation.python.3.12_qbz5n2kfra8p0\\localcache\\local-packages\\python312\\site-packages (from tensorboard<2.19,>=2.18->tensorflow-intel==2.18.0->tensorflow) (3.1.3)\n",
      "Requirement already satisfied: MarkupSafe>=2.1.1 in c:\\users\\acer\\appdata\\local\\packages\\pythonsoftwarefoundation.python.3.12_qbz5n2kfra8p0\\localcache\\local-packages\\python312\\site-packages (from werkzeug>=1.0.1->tensorboard<2.19,>=2.18->tensorflow-intel==2.18.0->tensorflow) (3.0.2)\n",
      "Requirement already satisfied: markdown-it-py>=2.2.0 in c:\\users\\acer\\appdata\\local\\packages\\pythonsoftwarefoundation.python.3.12_qbz5n2kfra8p0\\localcache\\local-packages\\python312\\site-packages (from rich->keras>=3.5.0->tensorflow-intel==2.18.0->tensorflow) (3.0.0)\n",
      "Requirement already satisfied: pygments<3.0.0,>=2.13.0 in c:\\users\\acer\\appdata\\local\\packages\\pythonsoftwarefoundation.python.3.12_qbz5n2kfra8p0\\localcache\\local-packages\\python312\\site-packages (from rich->keras>=3.5.0->tensorflow-intel==2.18.0->tensorflow) (2.19.1)\n",
      "Requirement already satisfied: mdurl~=0.1 in c:\\users\\acer\\appdata\\local\\packages\\pythonsoftwarefoundation.python.3.12_qbz5n2kfra8p0\\localcache\\local-packages\\python312\\site-packages (from markdown-it-py>=2.2.0->rich->keras>=3.5.0->tensorflow-intel==2.18.0->tensorflow) (0.1.2)\n",
      "Using cached tensorflow-2.18.0-cp312-cp312-win_amd64.whl (7.5 kB)\n",
      "Using cached tensorflow_intel-2.18.0-cp312-cp312-win_amd64.whl (390.3 MB)\n",
      "Installing collected packages: tensorflow-intel, tensorflow\n"
     ]
    },
    {
     "name": "stderr",
     "output_type": "stream",
     "text": [
      "ERROR: Could not install packages due to an OSError: [Errno 2] No such file or directory: 'C:\\\\Users\\\\acer\\\\AppData\\\\Local\\\\Packages\\\\PythonSoftwareFoundation.Python.3.12_qbz5n2kfra8p0\\\\LocalCache\\\\local-packages\\\\Python312\\\\site-packages\\\\tensorflow\\\\include\\\\external\\\\com_github_grpc_grpc\\\\src\\\\core\\\\ext\\\\filters\\\\client_channel\\\\lb_policy\\\\grpclb\\\\client_load_reporting_filter.h'\n",
      "HINT: This error might have occurred since this system does not have Windows Long Path support enabled. You can find information on how to enable this at https://pip.pypa.io/warnings/enable-long-paths\n",
      "\n"
     ]
    }
   ],
   "source": [
    "!pip  install --user tensorflow  "
   ]
  },
  {
   "cell_type": "code",
   "execution_count": 29,
   "metadata": {},
   "outputs": [],
   "source": [
    "import numpy as np\n",
    "import pandas as pd\n",
    "import matplotlib.pyplot as plt\n",
    "import cv2\n",
    "from tqdm import tqdm\n",
    "import warnings\n",
    "warnings.filterwarnings('ignore')"
   ]
  },
  {
   "cell_type": "code",
   "execution_count": 30,
   "metadata": {},
   "outputs": [],
   "source": [
    "train_path = \"dataset/TRAIN\"\n",
    "test_path = \"dataset/TEST\""
   ]
  },
  {
   "cell_type": "code",
   "execution_count": 33,
   "metadata": {},
   "outputs": [
    {
     "ename": "ModuleNotFoundError",
     "evalue": "No module named 'tensorflow.python'",
     "output_type": "error",
     "traceback": [
      "\u001b[1;31m---------------------------------------------------------------------------\u001b[0m",
      "\u001b[1;31mModuleNotFoundError\u001b[0m                       Traceback (most recent call last)",
      "Cell \u001b[1;32mIn[33], line 1\u001b[0m\n\u001b[1;32m----> 1\u001b[0m \u001b[38;5;28;01mfrom\u001b[39;00m\u001b[38;5;250m \u001b[39m\u001b[38;5;21;01mtensorflow\u001b[39;00m\u001b[38;5;21;01m.\u001b[39;00m\u001b[38;5;21;01mkeras\u001b[39;00m\u001b[38;5;21;01m.\u001b[39;00m\u001b[38;5;21;01mmodels\u001b[39;00m\u001b[38;5;250m \u001b[39m\u001b[38;5;28;01mimport\u001b[39;00m Sequential\n\u001b[0;32m      2\u001b[0m \u001b[38;5;28;01mfrom\u001b[39;00m\u001b[38;5;250m \u001b[39m\u001b[38;5;21;01mtensorflow\u001b[39;00m\u001b[38;5;21;01m.\u001b[39;00m\u001b[38;5;21;01mkeras\u001b[39;00m\u001b[38;5;21;01m.\u001b[39;00m\u001b[38;5;21;01mlayers\u001b[39;00m\u001b[38;5;250m \u001b[39m\u001b[38;5;28;01mimport\u001b[39;00m Conv2D, MaxPooling2D, Activation, Dropout, Flatten, Dense, BatchNormalization\n\u001b[0;32m      3\u001b[0m \u001b[38;5;28;01mfrom\u001b[39;00m\u001b[38;5;250m \u001b[39m\u001b[38;5;21;01mtensorflow\u001b[39;00m\u001b[38;5;21;01m.\u001b[39;00m\u001b[38;5;21;01mkeras\u001b[39;00m\u001b[38;5;21;01m.\u001b[39;00m\u001b[38;5;21;01mpreprocessing\u001b[39;00m\u001b[38;5;21;01m.\u001b[39;00m\u001b[38;5;21;01mimage\u001b[39;00m\u001b[38;5;250m \u001b[39m\u001b[38;5;28;01mimport\u001b[39;00m ImageDataGenerator, img_to_array, load_img\n",
      "File \u001b[1;32m~\\AppData\\Local\\Packages\\PythonSoftwareFoundation.Python.3.12_qbz5n2kfra8p0\\LocalCache\\local-packages\\Python312\\site-packages\\tensorflow\\__init__.py:40\u001b[0m\n\u001b[0;32m     37\u001b[0m _os\u001b[38;5;241m.\u001b[39menviron\u001b[38;5;241m.\u001b[39msetdefault(\u001b[38;5;124m\"\u001b[39m\u001b[38;5;124mENABLE_RUNTIME_UPTIME_TELEMETRY\u001b[39m\u001b[38;5;124m\"\u001b[39m, \u001b[38;5;124m\"\u001b[39m\u001b[38;5;124m1\u001b[39m\u001b[38;5;124m\"\u001b[39m)\n\u001b[0;32m     39\u001b[0m \u001b[38;5;66;03m# Do not remove this line; See https://github.com/tensorflow/tensorflow/issues/42596\u001b[39;00m\n\u001b[1;32m---> 40\u001b[0m \u001b[38;5;28;01mfrom\u001b[39;00m\u001b[38;5;250m \u001b[39m\u001b[38;5;21;01mtensorflow\u001b[39;00m\u001b[38;5;21;01m.\u001b[39;00m\u001b[38;5;21;01mpython\u001b[39;00m\u001b[38;5;250m \u001b[39m\u001b[38;5;28;01mimport\u001b[39;00m pywrap_tensorflow \u001b[38;5;28;01mas\u001b[39;00m _pywrap_tensorflow  \u001b[38;5;66;03m# pylint: disable=unused-import\u001b[39;00m\n\u001b[0;32m     41\u001b[0m \u001b[38;5;28;01mfrom\u001b[39;00m\u001b[38;5;250m \u001b[39m\u001b[38;5;21;01mtensorflow\u001b[39;00m\u001b[38;5;21;01m.\u001b[39;00m\u001b[38;5;21;01mpython\u001b[39;00m\u001b[38;5;21;01m.\u001b[39;00m\u001b[38;5;21;01mtools\u001b[39;00m\u001b[38;5;250m \u001b[39m\u001b[38;5;28;01mimport\u001b[39;00m module_util \u001b[38;5;28;01mas\u001b[39;00m _module_util\n\u001b[0;32m     42\u001b[0m \u001b[38;5;28;01mfrom\u001b[39;00m\u001b[38;5;250m \u001b[39m\u001b[38;5;21;01mtensorflow\u001b[39;00m\u001b[38;5;21;01m.\u001b[39;00m\u001b[38;5;21;01mpython\u001b[39;00m\u001b[38;5;21;01m.\u001b[39;00m\u001b[38;5;21;01mutil\u001b[39;00m\u001b[38;5;21;01m.\u001b[39;00m\u001b[38;5;21;01mlazy_loader\u001b[39;00m\u001b[38;5;250m \u001b[39m\u001b[38;5;28;01mimport\u001b[39;00m KerasLazyLoader \u001b[38;5;28;01mas\u001b[39;00m _KerasLazyLoader\n",
      "\u001b[1;31mModuleNotFoundError\u001b[0m: No module named 'tensorflow.python'"
     ]
    }
   ],
   "source": [
    "from tensorflow.keras.models import Sequential\n",
    "from tensorflow.keras.layers import Conv2D, MaxPooling2D, Activation, Dropout, Flatten, Dense, BatchNormalization\n",
    "from tensorflow.keras.preprocessing.image import ImageDataGenerator, img_to_array, load_img\n",
    "from tensorflow.keras.utils import plot_model\n",
    "from glob import glob"
   ]
  },
  {
   "cell_type": "code",
   "execution_count": 7,
   "metadata": {},
   "outputs": [
    {
     "ename": "NameError",
     "evalue": "name 'glob' is not defined",
     "output_type": "error",
     "traceback": [
      "\u001b[1;31m---------------------------------------------------------------------------\u001b[0m",
      "\u001b[1;31mNameError\u001b[0m                                 Traceback (most recent call last)",
      "Cell \u001b[1;32mIn[7], line 4\u001b[0m\n\u001b[0;32m      2\u001b[0m x_data \u001b[38;5;241m=\u001b[39m []\n\u001b[0;32m      3\u001b[0m y_data \u001b[38;5;241m=\u001b[39m []\n\u001b[1;32m----> 4\u001b[0m \u001b[38;5;28;01mfor\u001b[39;00m category \u001b[38;5;129;01min\u001b[39;00m \u001b[43mglob\u001b[49m(train_path\u001b[38;5;241m+\u001b[39m\u001b[38;5;124m'\u001b[39m\u001b[38;5;124m/*\u001b[39m\u001b[38;5;124m'\u001b[39m):\n\u001b[0;32m      5\u001b[0m     \u001b[38;5;28;01mfor\u001b[39;00m file \u001b[38;5;129;01min\u001b[39;00m tqdm(glob(category\u001b[38;5;241m+\u001b[39m\u001b[38;5;124m'\u001b[39m\u001b[38;5;124m/*\u001b[39m\u001b[38;5;124m'\u001b[39m)):\n\u001b[0;32m      6\u001b[0m         img_array \u001b[38;5;241m=\u001b[39m cv2\u001b[38;5;241m.\u001b[39mimread(file)\n",
      "\u001b[1;31mNameError\u001b[0m: name 'glob' is not defined"
     ]
    }
   ],
   "source": [
    "from cv2 import cvtColor\n",
    "x_data = []\n",
    "y_data = []\n",
    "for category in glob(train_path+'/*'):\n",
    "    for file in tqdm(glob(category+'/*')):\n",
    "        img_array = cv2.imread(file)\n",
    "        img_array = cvtcolor(img_array, COLOR_BGR2RGB)\n",
    "        x_data.append(img_array)\n",
    "        y_data.append(category.split('/')[-1])\n",
    "data = pd.DataFrame({'image':x_data,'label':y_data})"
   ]
  },
  {
   "cell_type": "code",
   "execution_count": 46,
   "metadata": {},
   "outputs": [
    {
     "ename": "NameError",
     "evalue": "name 'data' is not defined",
     "output_type": "error",
     "traceback": [
      "\u001b[1;31m---------------------------------------------------------------------------\u001b[0m",
      "\u001b[1;31mNameError\u001b[0m                                 Traceback (most recent call last)",
      "Cell \u001b[1;32mIn[46], line 2\u001b[0m\n\u001b[0;32m      1\u001b[0m plt\u001b[38;5;241m.\u001b[39mfigure(figsize\u001b[38;5;241m=\u001b[39m(\u001b[38;5;241m8\u001b[39m, \u001b[38;5;241m8\u001b[39m))\n\u001b[1;32m----> 2\u001b[0m plt\u001b[38;5;241m.\u001b[39mpie(\u001b[43mdata\u001b[49m\u001b[38;5;241m.\u001b[39mlabel\u001b[38;5;241m.\u001b[39mvalue_counts(), labels\u001b[38;5;241m=\u001b[39m[\u001b[38;5;124m'\u001b[39m\u001b[38;5;124mOrganic\u001b[39m\u001b[38;5;124m'\u001b[39m, \u001b[38;5;124m'\u001b[39m\u001b[38;5;124mRecyclable\u001b[39m\u001b[38;5;124m'\u001b[39m], autopct\u001b[38;5;241m=\u001b[39m\u001b[38;5;124m'\u001b[39m\u001b[38;5;132;01m%1.1f\u001b[39;00m\u001b[38;5;132;01m%%\u001b[39;00m\u001b[38;5;124m'\u001b[39m, startangle\u001b[38;5;241m=\u001b[39m\u001b[38;5;241m90\u001b[39m, colors\u001b[38;5;241m=\u001b[39mplt\u001b[38;5;241m.\u001b[39mcm\u001b[38;5;241m.\u001b[39mPaired\u001b[38;5;241m.\u001b[39mcolors)\n\u001b[0;32m      3\u001b[0m plt\u001b[38;5;241m.\u001b[39mtitle(\u001b[38;5;124m'\u001b[39m\u001b[38;5;124mProportion of Waste Types\u001b[39m\u001b[38;5;124m'\u001b[39m, fontsize\u001b[38;5;241m=\u001b[39m\u001b[38;5;241m16\u001b[39m)\n\u001b[0;32m      4\u001b[0m plt\u001b[38;5;241m.\u001b[39mshow()\n",
      "\u001b[1;31mNameError\u001b[0m: name 'data' is not defined"
     ]
    },
    {
     "data": {
      "text/plain": [
       "<Figure size 800x800 with 0 Axes>"
      ]
     },
     "metadata": {},
     "output_type": "display_data"
    }
   ],
   "source": [
    "plt.figure(figsize=(8, 8))\n",
    "plt.pie(data.label.value_counts(), labels=['Organic', 'Recyclable'], autopct='%1.1f%%', startangle=90, colors=plt.cm.Paired.colors)\n",
    "plt.title('Proportion of Waste Types', fontsize=16)\n",
    "plt.show()\n"
   ]
  }
 ],
 "metadata": {
  "kernelspec": {
   "display_name": "Python 3",
   "language": "python",
   "name": "python3"
  },
  "language_info": {
   "codemirror_mode": {
    "name": "ipython",
    "version": 3
   },
   "file_extension": ".py",
   "mimetype": "text/x-python",
   "name": "python",
   "nbconvert_exporter": "python",
   "pygments_lexer": "ipython3",
   "version": "3.12.8"
  }
 },
 "nbformat": 4,
 "nbformat_minor": 2
}
